{
  "cve_id": "CVE-2023-26303",
  "github_data": {
    "repository": "executablebooks/markdown-it-py",
    "fix_commit": "ae03c6107dfa18e648f6fdd1280f5b89092d5d49",
    "related_commits": [
      "ae03c6107dfa18e648f6fdd1280f5b89092d5d49",
      "ae03c6107dfa18e648f6fdd1280f5b89092d5d49"
    ],
    "patch_url": null
  },
  "vulnerability_details": {
    "cvss_score": 3.3,
    "cvss_vector": "CVSS:3.1/AV:L/AC:L/PR:L/UI:N/S:U/C:N/I:N/A:L",
    "cwe_id": "CWE-173",
    "description": "Denial of service could be caused to markdown-it-py, before v2.2.0, if an attacker was allowed to force null assertions with specially crafted input.\n",
    "attack_vector": "LOCAL",
    "attack_complexity": "LOW"
  },
  "temporal_data": {
    "published_date": "2023-02-23T00:15:11.390",
    "last_modified": "2024-11-21T07:51:05.900",
    "fix_date": null
  },
  "references": [
    {
      "url": "https://github.com/executablebooks/markdown-it-py/commit/ae03c6107dfa18e648f6fdd1280f5b89092d5d49",
      "source": "security@ubuntu.com",
      "tags": [
        "Patch"
      ]
    },
    {
      "url": "https://github.com/executablebooks/markdown-it-py/commit/ae03c6107dfa18e648f6fdd1280f5b89092d5d49",
      "source": "af854a3a-2127-422b-91ae-364da2661108",
      "tags": [
        "Patch"
      ]
    }
  ],
  "collection_metadata": {
    "collected_at": "2025-01-11T23:05:06.764176",
    "processing_status": "raw"
  }
}