{
  "cve_id": "CVE-2024-53432",
  "github_data": {
    "repository": "PointCloudLibrary/pcl",
    "fix_commit": null,
    "related_commits": [],
    "patch_url": null
  },
  "vulnerability_details": {
    "cvss_score": 7.5,
    "cvss_vector": "CVSS:3.1/AV:N/AC:L/PR:N/UI:N/S:U/C:N/I:N/A:H",
    "cwe_id": "CWE-754",
    "description": "While parsing certain malformed PLY files, PCL version 1.14.1 crashes due to an uncaught std::out_of_range exception in PCLPointCloud2::at. This issue could potentially be exploited to cause a denial-of-service (DoS) attack when processing untrusted PLY files.",
    "attack_vector": "NETWORK",
    "attack_complexity": "LOW"
  },
  "temporal_data": {
    "published_date": "2024-11-21T18:15:14.420",
    "last_modified": "2024-12-04T16:15:26.240",
    "fix_date": null
  },
  "references": [
    {
      "url": "https://github.com/PointCloudLibrary/pcl/issues/6162",
      "source": "cve@mitre.org",
      "tags": []
    }
  ],
  "collection_metadata": {
    "collected_at": "2025-01-11T23:09:31.278331",
    "processing_status": "raw"
  }
}